Workbook

Sheet Sheet1
A1: Value | B1: Position | C1: Label | D1: Values | F1: Measurement Level | G1: Role | H1: Column Width | I1: Alignment | J1: Missing Values | K1: Derived or questionnaire variable | L1: Notes/comments on dervied variables
A2: qcountry | B2: =VLOOKUP(A2,Sheet2!I:J,2,FALSE) -> 1 | C2: =VLOOKUP(A2,Sheet2!A:B,2,FALSE) -> QCOUNTRY. Country School is in | D2: 1.00 | E2: England | F2: Nominal | G2: Input | H2: =VLOOKUP(A2,Sheet2!L:M,2,FALSE) -> 10 | I2: Right | J2: -99
B3: =VLOOKUP(A3,Sheet2!I:J,2,FALSE) -> #N/A | C3: =VLOOKUP(A3,Sheet2!A:B,2,FALSE) -> #N/A | D3: 2.00 | E3: Wales | F3: Nominal | G3: Input | H3: =VLOOKUP(A3,Sheet2!L:M,2,FALSE) -> #N/A | I3: Right | J3: -99
B4: =VLOOKUP(A4,Sheet2!I:J,2,FALSE) -> #N/A | C4: =VLOOKUP(A4,Sheet2!A:B,2,FALSE) -> #N/A | D4: 3.00 | E4: Scotland | F4: Nominal | G4: Input | H4: =VLOOKUP(A4,Sheet2!L:M,2,FALSE) -> #N/A | I4: Right | J4: -99
B5: =VLOOKUP(A5,Sheet2!I:J,2,FALSE) -> #N/A | C5: =VLOOKUP(A5,Sheet2!A:B,2,FALSE) -> #N/A | D5: 4.00 | E5: Not stated/not answered | F5: Nominal | G5: Input | H5: =VLOOKUP(A5,Sheet2!L:M,2,FALSE) -> #N/A | I5: Right | J5: -99
A6: problem1 | B6: =VLOOKUP(A6,Sheet2!I:J,2,FALSE) -> 2 | C6: =VLOOKUP(A6,Sheet2!A:B,2,FALSE) -> Problem gambler: Respondents who have gambled in the last 12 months with their own money | D6: .00 | E6: no Respondents who have gambled in the last 12 months with their own money | F6: Nominal | G6: Input | H6: =VLOOKUP(A6,Sheet2!L:M,2,FALSE) -> 10 | I6: Right | J6: -99
B7: =VLOOKUP(A7,Sheet2!I:J,2,FALSE) -> #N/A | C7: =VLOOKUP(A7,Sheet2!A:B,2,FALSE) -> #N/A | D7: 1.00 | E7: Respondents who have gambled in the last 12 months with their own money | F7: Nominal | G7: Input | H7: =VLOOKUP(A7,Sheet2!L:M,2,FALSE) -> #N/A | I7: Right | J7: -99
A8: problem2 | B8: =VLOOKUP(A8,Sheet2!I:J,2,FALSE) -> 3 | C8: =VLOOKUP(A8,Sheet2!A:B,2,FALSE) -> Problem gambler: Non-problem gambler | D8: .00 | E8: no Non-problem gambler | F8: Nominal | G8: Input | H8: =VLOOKUP(A8,Sheet2!L:M,2,FALSE) -> 10 | I8: Right | J8: -99
B9: =VLOOKUP(A9,Sheet2!I:J,2,FALSE) -> #N/A | C9: =VLOOKUP(A9,Sheet2!A:B,2,FALSE) -> #N/A | D9: 1.00 | E9: Non-problem gambler | F9: Nominal | G9: Input | H9: =VLOOKUP(A9,Sheet2!L:M,2,FALSE) -> #N/A | I9: Right | J9: -99
A10: problem3 | B10: =VLOOKUP(A10,Sheet2!I:J,2,FALSE) -> 4 | C10: =VLOOKUP(A10,Sheet2!A:B,2,FALSE) -> Problem gambler: At risk | D10: .00 | E10: no At risk | F10: Nominal | G10: Input | H10: =VLOOKUP(A10,Sheet2!L:M,2,FALSE) -> 10 | I10: Right | J10: -99
B11: =VLOOKUP(A11,Sheet2!I:J,2,FALSE) -> #N/A | C11: =VLOOKUP(A11,Sheet2!A:B,2,FALSE) -> #N/A | D11: 1.00 | E11: At risk | F11: Nominal | G11: Input | H11: =VLOOKUP(A11,Sheet2!L:M,2,FALSE) -> #N/A | I11: Right | J11: -99
A12: problem4 | B12: =VLOOKUP(A12,Sheet2!I:J,2,FALSE) -> 5 | C12: =VLOOKUP(A12,Sheet2!A:B,2,FALSE) -> Problem gambler: Problem | D12: .00 | E12: no Problem | F12: Nominal | G12: Input | H12: =VLOOKUP(A12,Sheet2!L:M,2,FALSE) -> 10 | I12: Right | J12: -99
B13: =VLOOKUP(A13,Sheet2!I:J,2,FALSE) -> #N/A | C13: =VLOOKUP(A13,Sheet2!A:B,2,FALSE) -> #N/A | D13: 1.00 | E13: Problem | F13: Nominal | G13: Input | H13: =VLOOKUP(A13,Sheet2!L:M,2,FALSE) -> #N/A | I13: Right | J13: -99
A14: problem5 | B14: =VLOOKUP(A14,Sheet2!I:J,2,FALSE) -> 6 | C14: =VLOOKUP(A14,Sheet2!A:B,2,FALSE) -> Problem gambler: Respondents who say prefer not to say to all problem gambling screening questions | D14: .00 | E14: no Respondents who say prefer not to say to all problem gambling screening questions | F14: Nominal | G14: Input | H14: =VLOOKUP(A14,Sheet2!L:M,2,FALSE) -> 10 | I14: Right | J14: -99
B15: =VLOOKUP(A15,Sheet2!I:J,2,FALSE) -> #N/A | C15: =VLOOKUP(A15,Sheet2!A:B,2,FALSE) -> #N/A | D15: 1.00 | E15: Respondents who say prefer not to say to all problem gambling screening questions | F15: Nominal | G15: Input | H15: =VLOOKUP(A15,Sheet2!L:M,2,FALSE) -> #N/A | I15: Right | J15: -99
A16: problem6 | B16: =VLOOKUP(A16,Sheet2!I:J,2,FALSE) -> 7 | C16: =VLOOKUP(A16,Sheet2!A:B,2,FALSE) -> Problem gambler: Not used own money in last 12 months/not gambled | D16: .00 | E16: no Not used own money in last 12 months/not gambled | F16: Nominal | G16: Input | H16: =VLOOKUP(A16,Sheet2!L:M,2,FALSE) -> 10 | I16: Right | J16: -99
B17: =VLOOKUP(A17,Sheet2!I:J,2,FALSE) -> #N/A | C17: =VLOOKUP(A17,Sheet2!A:B,2,FALSE) -> #N/A | D17: 1.00 | E17: Not used own money in last 12 months/not gambled | F17: Nominal | G17: Input | H17: =VLOOKUP(A17,Sheet2!L:M,2,FALSE) -> #N/A | I17: Right | J17: -99
A18: problem7 | B18: =VLOOKUP(A18,Sheet2!I:J,2,FALSE) -> 8 | C18: =VLOOKUP(A18,Sheet2!A:B,2,FALSE) -> Problem gambler: Never done any of the activities | D18: .00 | E18: no Never done any of the activities | F18: Nominal | G18: Input | H18: =VLOOKUP(A18,Sheet2!L:M,2,FALSE) -> 10 | I18: Right | J18: -99
B19: =VLOOKUP(A19,Sheet2!I:J,2,FALSE) -> #N/A | C19: =VLOOKUP(A19,Sheet2!A:B,2,FALSE) -> #N/A | D19: 1.00 | E19: Never done any of the activities | F19: Nominal | G19: Input | H19: =VLOOKUP(A19,Sheet2!L:M,2,FALSE) -> #N/A | I19: Right | J19: -99
A20: problem8 | B20: =VLOOKUP(A20,Sheet2!I:J,2,FALSE) -> 9 | C20: =VLOOKUP(A20,Sheet2!A:B,2,FALSE) -> Problem gambler: Not spent own money on any activity | D20: .00 | E20: no Not spent own money on any activity | F20: Nominal | G20: Input | H20: =VLOOKUP(A20,Sheet2!L:M,2,FALSE) -> 10 | I20: Right | J20: -99
B21: =VLOOKUP(A21,Sheet2!I:J,2,FALSE) -> #N/A | C21: =VLOOKUP(A21,Sheet2!A:B,2,FALSE) -> #N/A | D21: 1.00 | E21: Not spent own money on any activity | F21: Nominal | G21: Input | H21: =VLOOKUP(A21,Sheet2!L:M,2,FALSE) -> #N/A | I21: Right | J21: -99
A22: problem9 | B22: =VLOOKUP(A22,Sheet2!I:J,2,FALSE) -> 10 | C22: =VLOOKUP(A22,Sheet2!A:B,2,FALSE) -> Problem gambler: Used own money but not in the last 12 months | D22: .00 | E22: no Used own money but not in the last 12 months | F22: Nominal | G22: Input | H22: =VLOOKUP(A22,Sheet2!L:M,2,FALSE) -> 10 | I22: Right | J22: -99
B23: =VLOOKUP(A23,Sheet2!I:J,2,FALSE) -> #N/A | C23: =VLOOKUP(A23,Sheet2!A:B,2,FALSE) -> #N/A | D23: 1.00 | E23: Used own money but not in the last 12 months | F23: Nominal | G23: Input | H23: =VLOOKUP(A23,Sheet2!L:M,2,FALSE) -> #N/A | I23: Right | J23: -99
A24: problem10 | B24: =VLOOKUP(A24,Sheet2!I:J,2,FALSE) -> 11 | C24: =VLOOKUP(A24,Sheet2!A:B,2,FALSE) -> Problem gambler: Not stated/not answered | D24: .00 | E24: no Not stated/not answered | F24: Nominal | G24: Input | H24: =VLOOKUP(A24,Sheet2!L:M,2,FALSE) -> 11 | I24: Right | J24: -99
B25: =VLOOKUP(A25,Sheet2!I:J,2,FALSE) -> #N/A | C25: =VLOOKUP(A25,Sheet2!A:B,2,FALSE) -> #N/A | D25: 1.00 | E25: Not stated/not answered | F25: Nominal | G25: Input | H25: =VLOOKUP(A25,Sheet2!L:M,2,FALSE) -> #N/A | I25: Right | J25: -99
A26: problem11 | B26: =VLOOKUP(A26,Sheet2!I:J,2,FALSE) -> 12 | C26: =VLOOKUP(A26,Sheet2!A:B,2,FALSE) -> Problem gambler: Any regulated gambling | D26: .00 | E26: no Any regulated gambling | F26: Nominal | G26: Input | H26: =VLOOKUP(A26,Sheet2!L:M,2,FALSE) -> 11 | I26: Right | J26: -99
B27: =VLOOKUP(A27,Sheet2!I:J,2,FALSE) -> #N/A | C27: =VLOOKUP(A27,Sheet2!A:B,2,FALSE) -> #N/A | D27: 1.00 | E27: Any regulated gambling | F27: Nominal | G27: Input | H27: =VLOOKUP(A27,Sheet2!L:M,2,FALSE) -> #N/A | I27: Right | J27: -99
A28: problem12 | B28: =VLOOKUP(A28,Sheet2!I:J,2,FALSE) -> 13 | C28: =VLOOKUP(A28,Sheet2!A:B,2,FALSE) -> Problem gambler: Any unregulated gambling | D28: .00 | E28: no Any unregulated gambling | F28: Nominal | G28: Input | H28: =VLOOKUP(A28,Sheet2!L:M,2,FALSE) -> 11 | I28: Right | J28: -99
B29: =VLOOKUP(A29,Sheet2!I:J,2,FALSE) -> #N/A | C29: =VLOOKUP(A29,Sheet2!A:B,2,FALSE) -> #N/A | D29: 1.00 | E29: Any unregulated gambling | F29: Nominal | G29: Input | H29: =VLOOKUP(A29,Sheet2!L:M,2,FALSE) -> #N/A | I29: Right | J29: -99
A30: problem13 | B30: =VLOOKUP(A30,Sheet2!I:J,2,FALSE) -> 14 | C30: =VLOOKUP(A30,Sheet2!A:B,2,FALSE) -> Problem gambler: Any regulated gambling without arcade machines | D30: .00 | E30: no Any regulated gambling without arcade machines | F30: Nominal | G30: Input | H30: =VLOOKUP(A30,Sheet2!L:M,2,FALSE) -> 11 | I30: Right | J30: -99
B31: =VLOOKUP(A31,Sheet2!I:J,2,FALSE) -> #N/A | C31: =VLOOKUP(A31,Sheet2!A:B,2,FALSE) -> #N/A | D31: 1.00 | E31: Any regulated gambling without arcade machines | F31: Nominal | G31: Input | H31: =VLOOKUP(A31,Sheet2!L:M,2,FALSE) -> #N/A | I31: Right | J31: -99
A32: gamspenda1 | B32: =VLOOKUP(A32,Sheet2!I:J,2,FALSE) -> 15 | C32: =VLOOKUP(A32,Sheet2!A:B,2,FALSE) -> GC_GAMSPENDWHEN. When did you last do... Summary of gambling in the last 7 days? Was it...?: National Lottery draw e.g. Lotto, EuroMillions or Set for Life, either with a physical ticket or playing online | D32: .00 | E32: no National Lottery draw e.g. Lotto, EuroMillions or Set for Life, either with a physical ticket or playing online | F32: Nominal | G32: Input | H32: =VLOOKUP(A32,Sheet2!L:M,2,FALSE) -> 12 | I32: Right | J32: -99
B33: =VLOOKUP(A33,Sheet2!I:J,2,FALSE) -> #N/A | C33: =VLOOKUP(A33,Sheet2!A:B,2,FALSE) -> #N/A | D33: 1.00 | E33: National Lottery draw e.g. Lotto, EuroMillions or Set for Life, either with a physical ticket or playing online | F33: Nominal | G33: Input | H33: =VLOOKUP(A33,Sheet2!L:M,2,FALSE) -> #N/A | I33: Right | J33: -99
A34: gamspenda2 | B34: =VLOOKUP(A34,Sheet2!I:J,2,FALSE) -> 16 | C34: =VLOOKUP(A34,Sheet2!A:B,2,FALSE) -> GC_GAMSPENDWHEN. When did you last do... Summary of gambling in the last 7 days? Was it...?: National Lottery Scratchcards (not free Scratchcards) | D34: .00 | E34: no National Lottery Scratchcards (not free Scratchcards) | F34: Nominal | G34: Input | H34: =VLOOKUP(A34,Sheet2!L:M,2,FALSE) -> 12 | I34: Right | J34: -99
B35: =VLOOKUP(A35,Sheet2!I:J,2,FALSE) -> #N/A | C35: =VLOOKUP(A35,Sheet2!A:B,2,FALSE) -> #N/A | D35: 1.00 | E35: National Lottery Scratchcards (not free Scratchcards) | F35: Nominal | G35: Input | H35: =VLOOKUP(A35,Sheet2!L:M,2,FALSE) -> #N/A | I35: Right | J35: -99
A36: gamspenda3 | B36: =VLOOKUP(A36,Sheet2!I:J,2,FALSE) -> 17 | C36: =VLOOKUP(A36,Sheet2!A:B,2,FALSE) -> GC_GAMSPENDWHEN. When did you last do... Summary of gambling in the last 7 days? Was it...?: National Lottery online instant win games | D36: .00 | E36: no National Lottery online instant win games | F36: Nominal | G36: Input | H36: =VLOOKUP(A36,Sheet2!L:M,2,FALSE) -> 12 | I36: Right | J36: -99
B37: =VLOOKUP(A37,Sheet2!I:J,2,FALSE) -> #N/A | C37: =VLOOKUP(A37,Sheet2!A:B,2,FALSE) -> #N/A | D37: 1.00 | E37: National Lottery online instant win games | F37: Nominal | G37: Input | H37: =VLOOKUP(A37,Sheet2!L:M,2,FALSE) -> #N/A | I37: Right | J37: -99
A38: gamspenda4 | B38: =VLOOKUP(A38,Sheet2!I:J,2,FALSE) -> 18 | C38: =VLOOKUP(A38,Sheet2!A:B,2,FALSE) -> GC_GAMSPENDWHEN. When did you last do... Summary of gambling in the last 7 days? Was it...?: Other Lotteries (e.g. The Health Lottery, People's Postcode Lottery, or other smaller lotteries) | D38: .00 | E38: no Other Lotteries (e.g. The Health Lottery, People's Postcode Lottery, or other smaller lotteries) | F38: Nominal | G38: Input | H38: =VLOOKUP(A38,Sheet2!L:M,2,FALSE) -> 12 | I38: Right | J38: -99
B39: =VLOOKUP(A39,Sheet2!I:J,2,FALSE) -> #N/A | C39: =VLOOKUP(A39,Sheet2!A:B,2,FALSE) -> #N/A | D39: 1.00 | E39: Other Lotteries (e.g. The Health Lottery, People's Postcode Lottery, or other smaller lotteries) | F39: Nominal | G39: Input | H39: =VLOOKUP(A39,Sheet2!L:M,2,FALSE) -> #N/A | I39: Right | J39: -99
A40: gamspenda5 | B40: =VLOOKUP(A40,Sheet2!I:J,2,FALSE) -> 19 | C40: =VLOOKUP(A40,Sheet2!A:B,2,FALSE) -> GC_GAMSPENDWHEN. When did you last do... Summary of gambling in the last 7 days? Was it...?: Played arcade gaming machines (e.g. penny pusher or claw grab machine) | D40: .00 | E40: no Played arcade gaming machines (e.g. penny pusher or claw grab machine) | F40: Nominal | G40: Input | H40: =VLOOKUP(A40,Sheet2!L:M,2,FALSE) -> 12 | I40: Right | J40: -99
...

Sheet Sheet2
I1: Variable Values
A2: Variable | B2: Label | I2: Value | L2: Variable | M2: Column Width
A3: qcountry | B3: QCOUNTRY. Country School is in | I3: qcountry | J3: 1 | L3: qcountry | M3: 10
A4: problem1 | B4: Problem gambler: Respondents who have gambled in the last 12 months with their own money | I4: problem1 | J4: 2 | L4: problem1 | M4: 10
A5: problem2 | B5: Problem gambler: Non-problem gambler | I5: problem2 | J5: 3 | L5: problem2 | M5: 10
A6: problem3 | B6: Problem gambler: At risk | I6: problem3 | J6: 4 | L6: problem3 | M6: 10
A7: problem4 | B7: Problem gambler: Problem | I7: problem4 | J7: 5 | L7: problem4 | M7: 10
A8: problem5 | B8: Problem gambler: Respondents who say prefer not to say to all problem gambling screening questions | I8: problem5 | J8: 6 | L8: problem5 | M8: 10
A9: problem6 | B9: Problem gambler: Not used own money in last 12 months/not gambled | I9: problem6 | J9: 7 | L9: problem6 | M9: 10
A10: problem7 | B10: Problem gambler: Never done any of the activities | I10: problem7 | J10: 8 | L10: problem7 | M10: 10
A11: problem8 | B11: Problem gambler: Not spent own money on any activity | I11: problem8 | J11: 9 | L11: problem8 | M11: 10
A12: problem9 | B12: Problem gambler: Used own money but not in the last 12 months | I12: problem9 | J12: 10 | L12: problem9 | M12: 10
A13: problem10 | B13: Problem gambler: Not stated/not answered | I13: problem10 | J13: 11 | L13: problem10 | M13: 11
A14: problem11 | B14: Problem gambler: Any regulated gambling | I14: problem11 | J14: 12 | L14: problem11 | M14: 11
... A1299: ethnicity2 | B1299: ETHNICITY. Which of the following best describes you? | I1299: ethnicity2 | J1299: 1297 | L1299: ethnicity2 | M1299: 12
A1300: serial | B1300: Serial number
A1301: schoolid | B1301: School ID number
A1302: exage | B1302: Exact age
A1303: weight0 | B1303: <none>
